<?xml version="1.0"?>
<robot xmlns:xacro="http://www.ros.org/wiki/xacro" name="robot">
  <xacro:property name="mesh_path" value="$(find polebot_amr_description)/meshes"/>
  <link name="base_footprint"/>

  <link name="base_link"/>

  <joint name="base_footprint_joint" type="fixed">
    <parent link="base_footprint"/>
    <child link="base_link"/>
    <origin xyz="0 0 0" rpy="0 0 0"/>
  </joint>

  <link name="chassis">
    <visual>
      <origin xyz="0 0 0" rpy="0 0 0"/>
      <geometry>
        <mesh filename="file://${mesh_path}/polebot_amr.stl" scale="0.001 0.001 0.001"/>
      </geometry>
      <material name="gray">
        <color rgba="0.6 0.6 0.6 1.0"/>
      </material>
    </visual>
    <collision>
      <origin xyz="0 0 0.428" rpy="0 0 3.14"/>
      <geometry>
        <box size="0.7 1.15 0.7"/>
      </geometry>
    </collision>
    <inertial>
      <origin xyz="0 0 0.35" rpy="0 0 0"/>
      <mass value="5.0"/> <!-- Poids réduit pour répartir avec roues -->
      <!-- Inertie recalculée de manière approximative -->
      <inertia ixx="0.41" ixy="0" ixz="0" iyy="0.755" iyz="0" izz="0.755"/>
    </inertial>
  </link>

  <joint name="base_joint" type="fixed">
    <parent link="base_link"/>
    <child link="chassis"/>
    <origin xyz="0 0 0" rpy="0 0 0"/>
  </joint>
  
  <link name="left_wheel">
    <inertial>
      <origin xyz="0 0 0" rpy="0 0 0"/>
      <mass value="1.5"/> <!-- ↖ Plus lourd -->
      <inertia
        ixx="0.003" ixy="0.0" ixz="0.0"
        iyy="0.003" iyz="0.0"
        izz="0.002"/>
    </inertial>
    <collision>
      <geometry>
        <cylinder radius="0.07" length="0.05"/>
      </geometry>
      <origin xyz="0 0 0" rpy="0 0 0"/>
      <surface>
        <friction>
          <ode>
            <mu>1.0</mu>
            <mu2>0.0</mu2>
          </ode>
        </friction>
      </surface>
    </collision>
  </link>

  <joint name="left_wheel_joint" type="continuous">
    <parent link="base_link"/>
    <child link="left_wheel"/>
    <origin xyz="0.375 0.3 0.07" rpy="1.57 0 1.57"/> <!-- Position à adapter -->
    <axis xyz="0 -1 0">
        <dynamics damping="1.0" friction="0.5"/>  <!-- Ajout ici -->
    </axis>
  </joint>  
  
   <link name="right_wheel">
    <inertial>
      <origin xyz="0 0 0" rpy="0 0 0"/>
      <mass value="1.5"/> <!-- ↖ Plus lourd -->
      <inertia
        ixx="0.003" ixy="0.0" ixz="0.0"
        iyy="0.003" iyz="0.0"
        izz="0.002"/>
    </inertial>
    <collision>
      <geometry>
        <cylinder radius="0.07" length="0.05"/>
      </geometry>
      <origin xyz="0 0 0" rpy="0 0 0"/>
      <surface>
        <friction>
          <ode>
            <mu>1.0</mu>
            <mu2>0.0</mu2>
          </ode>
        </friction>
      </surface>
    </collision>
  </link>

  <joint name="right_wheel_joint" type="continuous">
    <parent link="base_link"/>
    <child link="right_wheel"/>
    <origin xyz="-0.375 0.3 0.07" rpy="1.57 0 1.57"/> <!-- Position à adapter -->
    <axis xyz="0 -1 0">
        <dynamics damping="1.0" friction="0.5"/>  <!-- Ajout ici -->
    </axis>
  </joint>

  <link name="front_left_caster">
    <inertial>
      <mass value="1.5"/>
      <inertia ixx="0.41" ixy="0" ixz="0" iyy="0.755" iyz="0" izz="0.755"/>
    </inertial>
    <collision>
      <geometry>
        <cylinder radius="0.07" length="0.05"/>
      </geometry>
      <origin xyz="0 0 0" rpy="0 0 0"/>
      <surface>
        <friction>
          <ode>
            <mu>1.0</mu>
            <mu2>0.0</mu2>
          </ode>
        </friction>
      </surface>
    </collision>
  </link>

  <joint name="front_left_caster_joint" type="continuous">
    <parent link="base_link"/>
    <child link="front_left_caster"/>
    <origin xyz="0.375 -0.3 0.07" rpy="1.57 0 1.57"/> <!-- Position adaptée -->
    <axis xyz="0 -1 0"/>
  </joint>

  <link name="front_right_caster">
    <inertial>
      <mass value="1.5"/>
      <inertia ixx="0.41" ixy="0" ixz="0" iyy="0.755" iyz="0" izz="0.755"/>
    </inertial>
    <collision>
      <geometry>
        <cylinder radius="0.07" length="0.05"/>
      </geometry>
      <origin xyz="0 0 0" rpy="0 0 0"/>
      <surface>
        <friction>
          <ode>
            <mu>1.0</mu>
            <mu2>0.0</mu2>
          </ode>
        </friction>
      </surface>
    </collision>
  </link>

  <joint name="front_right_caster_joint" type="continuous">
    <parent link="base_link"/>
    <child link="front_right_caster"/>
    <origin xyz="-0.375 -0.3 0.07" rpy="1.57 0 1.57"/> <!-- Position adaptée -->
    <axis xyz="0 -1 0"/>
  </joint>

</robot>